Workbook
Name aaa: #REF!
Name aaa: #REF!
Name aaa: #REF!
Name aaa: #REF!
Name aaa: #REF!
Name daftar_rekom: '[1]Penjurusan SMA asli'!$K$6:$K$293
Name datagedeg: #REF!
Name datagedeg: #REF!
Name datagedeg: #REF!
Name datagedeg: #REF!
Name datagedeg: #REF!
Name datakediri: #REF!
Name datakediri: #REF!
Name datakediri: #REF!
Name datakediri: #REF!
Name datakediri: #REF!
Name datamoker: #REF!
Name datamoker: #REF!
Name datamoker: #REF!
Name datamoker: #REF!
Name datamoker: #REF!

Sheet INDUK
A1: PEMERINTAH PROVINSI JAWA TIMUR
A2: DINAS PENDIDIKAN
A3: SEKOLAH MENENGAH ATAS NEGERI 1 NGORO
A4: Jalan Candi Jolotundo, Kutogirang, Ngoro Tepepon : 0321-6819922
A5: Website : www.sman1ngoro.sch.id Email : smanngoro@gmail.com
A7: DATA NOMOR INDUK DAN DAN NAMA SISWA BARU
A8: TAHUN PELAJARAN 2026/2027
A10: NO | B10: NIS | C10: NAMA | D10: L/P | E10: KELAS | F10: KETERANGAN
A11: 1 | B11: 6272 | C11: ALVIRA FITRIATUN NIZHA | D11: P | E11: XI-9 | F11: Siswa Mutasi
A12: 2 | B12: 6273 | C12: ABDUL WAHID | D12: L | E12: X-5 | F12: Siswa Baru
A13: 3 | B13: 6274 | C13: ACHMAD AINUR RIZKY AKBHAR | D13: L | E13: X-6 | F13: Siswa Baru
A14: 4 | B14: 6275 | C14: ACHMAD ALBYANSYAH BISRI | D14: L | E14: X-4 | F14: Siswa Baru
A15: 5 | B15: 6276 | C15: ACHMAD MUSTOFA KAMAL PASA | D15: L | E15: X-2 | F15: Siswa Baru
A16: 6 | B16: 6277 | C16: ADELIA PUTRI AGUSTIN | D16: P | E16: X-6 | F16: Siswa Baru
A17: 7 | B17: 6278 | C17: ADELIA SIVANA PUTRI | D17: P | E17: X-3 | F17: Siswa Baru
A18: 8 | B18: 6279 | C18: ADELIA WAIDAH AZZAHIRA | D18: P | E18: X-3 | F18: Siswa Baru
A19: 9 | B19: 6280 | C19: ADISKA MUHAMMAD ZAHY | D19: L | E19: X-9 | F19: Siswa Baru
A20: 10 | B20: 6281 | C20: ADZRA SHABRIYAH YUMNAA | D20: P | E20: X-6 | F20: Siswa Baru
A21: 11 | B21: 6282 | C21: AGUSTIN DWI RAMADHANI | D21: P | E21: X-3 | F21: Siswa Baru
A22: 12 | B22: 6283 | C22: AGUSTINA FITRI RAHMADANI | D22: P | E22: X-7 | F22: Siswa Baru
... A332: 322 | B332: 6593 | C332: ZIVEN UBHAYAHITA HILYAHAZKA | D332: L | E332: X-7 | F332: Siswa Baru

Sheet ABSEN X
A1: PEMERINTAH PROVINSI JAWA TIMUR
A2: DINAS PENDIDIKAN
A3: SEKOLAH MENENGAH ATAS NEGERI 1 NGORO
A4: Jalan Candi Jolotundo, Kutogirang, Ngoro Tepepon : 0321-6819922
A5: Website : www.sman1ngoro.sch.id Email : smanngoro@gmail.com
A6: MOJOKERTO 61385
A8: DAFTAR HADIR SISWA
A10: KELAS | C10: : X-1 | D10: MATA PELAJARAN | K10: : | L10: ………………………………. | V10: L | W10: =COUNTIF(D16:$D$51,V10) -> 12
A11: SEMESTER : | C11: : GASAL | D11: TAHUN PELAJARAN | K11: : | L11: 2026/2027 | V11: P | W11: =COUNTIF(D16:$D$51,V11) -> 24
W12: =SUM(W10:W11) -> 36
A13: NOMOR | C13: NAMA SISWA | D13: L/P | E13: PERTEMUAN KE : ……..TANGGAL : ……. | Q13: ABSENSI
A14: URT | B14: INDUK | E14: 1 | F14: 2 | G14: 3 | H14: 4 | I14: 5 | J14: 6 | K14: 7 | L14: 8 | M14: 9 | N14: 10 | O14: 11 | P14: 12
Q15: S | R15: I | S15: A
A16: 1 | B16: 6287 | C16: AHMAD FIKRI MALIK ALFARUQ | D16: L
A17: 2 | B17: 6288 | C17: AHMAD FIRDAUS NURIL HUDA | D17: L
A18: 3 | B18: 6301 | C18: ALICA PUTRI CHISBIYAH | D18: P
A19: 4 | B19: 6308 | C19: ALYSHA ADELIA PUTRI | D19: P
A20: 5 | B20: 6312 | C20: ANDHARA DWIKE ANGGRAENI | D20: P
A21: 6 | B21: 6325 | C21: ARIFKA DWI AININ JARIYA | D21: P
A22: 7 | B22: 6326 | C22: ARLIANDA MAYRISKA | D22: P
A23: 8 | B23: 6327 | C23: ARRUM INDAH HAYUNINGTYAS | D23: P
A24: 9 | B24: 6342 | C24: BILQIS RAHMA AQILA | D24: P
A25: 10 | B25: 6350 | C25: CAMELIA NURMALA HIDAYAT | D25: P
A26: 11 | B26: 6358 | C26: CHOLIFATUN NISA AYU AZZAHRA | D26: P
A27: 12 | B27: 6373 | C27: DWI AULIA AURAKASIH | D27: P
... A51: 36 | B51: 6583 | C51: ZAHRA ANANDA APRILIA | D51: P
M53: Ngoro, ……………….…… 2026
A54: Mengetahui : | M54: Guru Mata Pelajaran
A55: Kepala SMA Negeri 1 Ngoro | D55: Wali Kelas X-1
A59: CHOIRUL IHSAN, S.Pd, M.M. | D59: KASIADI, S.Ag, M.Pd | M59: …..…………………………..
A60: NIP. 19720416 200801 1 019 | D60: NIP. 19720721 200604 1 009 | M60: …..…………………………..
A73: PEMERINTAH PROVINSI JAWA TIMUR
A74: DINAS PENDIDIKAN
A75: SEKOLAH MENENGAH ATAS NEGERI 1 NGORO
A76: Jalan Candi Jolotundo, Kutogirang, Ngoro Tepepon : 0321-6819922
A77: Website : www.sman1ngoro.sch.id Email : smanngoro@gmail.com
A78: MOJOKERTO 61385
A80: DAFTAR HADIR SISWA
A82: KELAS | C82: : X-2 | D82: MATA PELAJARAN | K82: : | L82: ……………………………….
A83: SEMESTER : | C83: : GASAL | D83: TAHUN PELAJARAN | K83: : | L83: 2026/2027
...

Sheet DN X 
A1: PEMERINTAH PROVINSI JAWA TIMUR
A2: DINAS PENDIDIKAN
A3: SEKOLAH MENENGAH ATAS NEGERI 1 NGORO
A4: Jalan Candi Jolotundo, Kutogirang, Ngoro Tepepon : 0321-6819922
A5: Website : www.sman1ngoro.sch.id Email : smanngoro@gmail.com
A6: MOJOKERTO 61385
A8: DAFTAR NILAI SISWA
A9: KELAS X-1
A10: MATA PELAJARAN : ………………………………….
A11: SEMESTER GASAL TAHUN PELAJARAN 2026/2027
A13: NOMOR | C13: NAMA SISWA | D13: L/P | E13: KD …………………… | L13: KD …………………… | S13: KD ……………………
E14: KOGNITIF | J14: PS | K14: AF | L14: KOGNITIF | Q14: PS | R14: AF | S14: KOGNITIF | X14: PS | Y14: AF
A15: URT | B15: IND. | E15: P | F15: T1 | G15: T2 | H15: UH | I15: R | L15: P | M15: T1 | N15: T2 | O15: UH | P15: R | S15: P | T15: T1 | U15: T2 | V15: UH | W15: R
A16: 1 | B16: 6287 | C16: AHMAD FIKRI MALIK ALFARUQ | D16: L
A17: 2 | B17: 6288 | C17: AHMAD FIRDAUS NURIL HUDA | D17: L
A18: 3 | B18: 6301 | C18: ALICA PUTRI CHISBIYAH | D18: P
A19: 4 | B19: 6308 | C19: ALYSHA ADELIA PUTRI | D19: P
A20: 5 | B20: 6312 | C20: ANDHARA DWIKE ANGGRAENI | D20: P
A21: 6 | B21: 6325 | C21: ARIFKA DWI AININ JARIYA | D21: P
A22: 7 | B22: 6326 | C22: ARLIANDA MAYRISKA | D22: P
A23: 8 | B23: 6327 | C23: ARRUM INDAH HAYUNINGTYAS | D23: P
A24: 9 | B24: 6342 | C24: BILQIS RAHMA AQILA | D24: P
A25: 10 | B25: 6350 | C25: CAMELIA NURMALA HIDAYAT | D25: P
A26: 11 | B26: 6358 | C26: CHOLIFATUN NISA AYU AZZAHRA | D26: P
A27: 12 | B27: 6373 | C27: DWI AULIA AURAKASIH | D27: P
... A51: 36 | B51: 6583 | C51: ZAHRA ANANDA APRILIA | D51: P
O53: Ngoro, ……………….…… 2026
B54: Wali Kelas X-1 | O54: Guru Mata Pelajaran ……..………………..
B58: KASIADI, S.Ag, M.Pd | O58: …..………………..…………………………..
B59: NIP. 19720721 200604 1 009 | O59: ……..……………..…………………………..
A63: PEMERINTAH PROVINSI JAWA TIMUR
A64: DINAS PENDIDIKAN
A65: SEKOLAH MENENGAH ATAS NEGERI 1 NGORO
A66: Jalan Candi Jolotundo, Kutogirang, Ngoro Tepepon : 0321-6819922
A67: Website : www.sman1ngoro.sch.id Email : smanngoro@gmail.com
A68: MOJOKERTO 61385
A70: DAFTAR NILAI SISWA
A71: KELAS X-2
A72: MATA PELAJARAN : ………………………………….
A73: SEMESTER GASAL TAHUN PELAJARAN 2026/2027
...

Sheet TERIMA RAPORT
A1: PEMERINTAH PROVINSI JAWA TIMUR
A2: DINAS PENDIDIKAN | H2: :
A3: SEKOLAH MENENGAH ATAS NEGERI 1 NGORO | H3: :
A4: Jalan Candi Jolotundo, Kutogirang, Ngoro Tepepon : 0321-6819922
A5: Website : www.sman1ngoro.sch.id Email : smanngoro@gmail.com
A6: MOJOKERTO 61385
A8: DAFTAR HADIR TERIMA RAPORT
A10: KELAS | C10: : X-1 | D10: HARI/TANGGAL | F10: : RABU, 23 DESEMBER 2026 | I10: L | J10: =COUNTIF(D16:$D$51,I10) -> 12
A11: SEMESTER : | C11: : GASAL | D11: TAHUN PELAJARAN | F11: : 2026/2027 | I11: P | J11: =COUNTIF(D16:$D$51,I11) -> 24
J12: =SUM(J10:J11) -> 36
A13: NOMOR | C13: NAMA SISWA | D13: L/P | E13: NAMA ORANG TUA/WALI | F13: TANDA TANAGAN
A14: URT | B14: INDUK
A16: 1 | B16: 6287 | C16: AHMAD FIKRI MALIK ALFARUQ | D16: L | F16: 1
A17: 2 | B17: 6288 | C17: AHMAD FIRDAUS NURIL HUDA | D17: L | F17: 2
A18: 3 | B18: 6301 | C18: ALICA PUTRI CHISBIYAH | D18: P | F18: 3
A19: 4 | B19: 6308 | C19: ALYSHA ADELIA PUTRI | D19: P | F19: 4
A20: 5 | B20: 6312 | C20: ANDHARA DWIKE ANGGRAENI | D20: P | F20: 5
A21: 6 | B21: 6325 | C21: ARIFKA DWI AININ JARIYA | D21: P | F21: 6
A22: 7 | B22: 6326 | C22: ARLIANDA MAYRISKA | D22: P | F22: 7
A23: 8 | B23: 6327 | C23: ARRUM INDAH HAYUNINGTYAS | D23: P | F23: 8
A24: 9 | B24: 6342 | C24: BILQIS RAHMA AQILA | D24: P | F24: 9
A25: 10 | B25: 6350 | C25: CAMELIA NURMALA HIDAYAT | D25: P | F25: 10
A26: 11 | B26: 6358 | C26: CHOLIFATUN NISA AYU AZZAHRA | D26: P | F26: 11
A27: 12 | B27: 6373 | C27: DWI AULIA AURAKASIH | D27: P | F27: 12
... A51: 36 | B51: 6583 | C51: ZAHRA ANANDA APRILIA | D51: P | F51: 36
A54: Mengetahui : | E54: Mojokerto, 23 Desember 2026
A55: Kepala SMA Negeri 1 Ngoro | E55: Wali Kelas X-1
A59: CHOIRUL IHSAN, S.Pd, MM | E59: KASIADI, S.Ag, M.Pd
A60: NIP. 19720416 200801 1 019 | E60: NIP. 19720721 200604 1 009
A73: PEMERINTAH PROVINSI JAWA TIMUR
A74: DINAS PENDIDIKAN
A75: SEKOLAH MENENGAH ATAS NEGERI 1 NGORO
A76: Jalan Candi Jolotundo, Kutogirang, Ngoro Tepepon : 0321-6819922
A77: Website : www.sman1ngoro.sch.id Email : smanngoro@gmail.com
A78: MOJOKERTO 61385
A80: DAFTAR HADIR TERIMA RAPORT
A82: KELAS | C82: : X-2 | D82: HARI/TANGGAL | F82: : RABU, 23 DESEMBER 2026
A83: SEMESTER : | C83: : GASAL | D83: TAHUN PELAJARAN | F83: : 2025/2026
A85: NOMOR | C85: NAMA SISWA | D85: L/P | E85: NAMA ORANG TUA/WALI | F85: TANDA TANAGAN
A86: URT | B86: INDUK
...

Sheet PARENTING 
A1: PEMERINTAH PROVINSI JAWA TIMUR
A2: DINAS PENDIDIKAN | H2: :
A3: SEKOLAH MENENGAH ATAS NEGERI 1 NGORO | H3: :
A4: Jalan Candi Jolotundo, Kutogirang, Ngoro Tepepon : 0321-6819922
A5: Website : www.sman1ngoro.sch.id Email : smanngoro@gmail.com
A6: MOJOKERTO 61385
A8: DAFTAR HADIR ORANG TUA SISWA
A9: KEGIATAN PARENTING & SOSIALISASI PROGRAM SEKOLAH
A11: KELAS | C11: : X-1 | D11: HARI/TANGGAL | F11: : SABTU, 11 JULI 2026 | I11: L | J11: =COUNTIF(D17:$D$52,I11) -> 12
A12: SEMESTER : | C12: : GASAL | D12: TAHUN PELAJARAN | F12: : 2026/2027 | I12: P | J12: =COUNTIF(D17:$D$52,I12) -> 24
J13: =SUM(J11:J12) -> 36
A14: NOMOR | C14: NAMA SISWA | D14: L/P | E14: NAMA ORANG TUA/WALI | F14: TANDA TANAGAN
A15: URT | B15: INDUK
A17: 1 | B17: 6287 | C17: AHMAD FIKRI MALIK ALFARUQ | D17: L | F17: 1
A18: 2 | B18: 6288 | C18: AHMAD FIRDAUS NURIL HUDA | D18: L | F18: 2
A19: 3 | B19: 6301 | C19: ALICA PUTRI CHISBIYAH | D19: P | F19: 3
A20: 4 | B20: 6308 | C20: ALYSHA ADELIA PUTRI | D20: P | F20: 4
A21: 5 | B21: 6312 | C21: ANDHARA DWIKE ANGGRAENI | D21: P | F21: 5
A22: 6 | B22: 6325 | C22: ARIFKA DWI AININ JARIYA | D22: P | F22: 6
A23: 7 | B23: 6326 | C23: ARLIANDA MAYRISKA | D23: P | F23: 7
A24: 8 | B24: 6327 | C24: ARRUM INDAH HAYUNINGTYAS | D24: P | F24: 8
A25: 9 | B25: 6342 | C25: BILQIS RAHMA AQILA | D25: P | F25: 9
A26: 10 | B26: 6350 | C26: CAMELIA NURMALA HIDAYAT | D26: P | F26: 10
A27: 11 | B27: 6358 | C27: CHOLIFATUN NISA AYU AZZAHRA | D27: P | F27: 11
A28: 12 | B28: 6373 | C28: DWI AULIA AURAKASIH | D28: P | F28: 12
... A51: 35 | B51: 6570 | C51: VARELYA CAHYA REZKYTA | D51: P | F51: 35
A52: 36 | B52: 6583 | C52: ZAHRA ANANDA APRILIA | D52: P
A54: Mengetahui : | E54: Mojokerto, 11 Juli 2026
A55: Kepala SMA Negeri 1 Ngoro | E55: Wali Kelas X-1
A59: CHOIRUL IHSAN, S.Pd, MM | E59: KASIADI, S.Ag, M.Pd
A60: NIP. 19720416 200801 1 019 | E60: NIP. 19720721 200604 1 009
A73: PEMERINTAH PROVINSI JAWA TIMUR
A74: DINAS PENDIDIKAN
A75: SEKOLAH MENENGAH ATAS NEGERI 1 NGORO
A76: Jalan Candi Jolotundo, Kutogirang, Ngoro Tepepon : 0321-6819922
A77: Website : www.sman1ngoro.sch.id Email : smanngoro@gmail.com
A78: MOJOKERTO 61385
A80: DAFTAR HADIR ORANG TUA SISWA
A81: KEGIATAN PARENTING & SOSIALISASI PROGRAM SEKOLAH
A83: KELAS | C83: : X-2 | D83: HARI/TANGGAL | F83: : SABTU, 11 JULI 2026
...

Sheet Guru Wali 
A1: PEMERINTAH PROVINSI JAWA TIMUR
A2: DINAS PENDIDIKAN
A3: SEKOLAH MENENGAH ATAS NEGERI 1 NGORO
A4: Jalan Candi Jolotundo, Kutogirang, Ngoro Tepepon : 0321-6819922
A5: Website : www.sman1ngoro.sch.id Email : smanngoro@gmail.com
A6: MOJOKERTO 61385
A8: DAFTAR HADIR SISWA
A10: KELAS | C10: : X-1 | D10: MATA PELAJARAN | K10: : | L10: ………………………………. | V10: L | W10: =COUNTIF(D16:$D$51,V10) -> 12
A11: SEMESTER : | C11: : GASAL | D11: TAHUN PELAJARAN | K11: : | L11: 2026/2027 | V11: P | W11: =COUNTIF(D16:$D$51,V11) -> 24
W12: =SUM(W10:W11) -> 36
A13: NOMOR | C13: NAMA SISWA | D13: L/P | E13: PERTEMUAN KE : ……..TANGGAL : ……. | Q13: ABSENSI
A14: URT | B14: INDUK | E14: 1 | F14: 2 | G14: 3 | H14: 4 | I14: 5 | J14: 6 | K14: 7 | L14: 8 | M14: 9 | N14: 10 | O14: 11 | P14: 12
Q15: S | R15: I | S15: A
A16: 1 | B16: 6287 | C16: AHMAD FIKRI MALIK ALFARUQ | D16: L | E16: Mohammad Mufid, S.PdI
A17: 2 | B17: 6288 | C17: AHMAD FIRDAUS NURIL HUDA | D17: L | E17: Mohammad Mufid, S.PdI
A18: 3 | B18: 6301 | C18: ALICA PUTRI CHISBIYAH | D18: P | E18: Mohammad Mufid, S.PdI
A19: 4 | B19: 6308 | C19: ALYSHA ADELIA PUTRI | D19: P | E19: Mohammad Mufid, S.PdI
A20: 5 | B20: 6312 | C20: ANDHARA DWIKE ANGGRAENI | D20: P | E20: Mohammad Mufid, S.PdI
A21: 6 | B21: 6325 | C21: ARIFKA DWI AININ JARIYA | D21: P | E21: Mohammad Mufid, S.PdI
A22: 7 | B22: 6326 | C22: ARLIANDA MAYRISKA | D22: P | E22: Mohammad Mufid, S.PdI
A23: 8 | B23: 6327 | C23: ARRUM INDAH HAYUNINGTYAS | D23: P | E23: Mohammad Mufid, S.PdI
A24: 9 | B24: 6342 | C24: BILQIS RAHMA AQILA | D24: P | E24: Mohammad Mufid, S.PdI
A25: 10 | B25: 6350 | C25: CAMELIA NURMALA HIDAYAT | D25: P | E25: Linda Nalurita, S.Pd
A26: 11 | B26: 6358 | C26: CHOLIFATUN NISA AYU AZZAHRA | D26: P | E26: Linda Nalurita, S.Pd
A27: 12 | B27: 6373 | C27: DWI AULIA AURAKASIH | D27: P | E27: Linda Nalurita, S.Pd
... A51: 36 | B51: 6583 | C51: ZAHRA ANANDA APRILIA | D51: P | E51: Imelda Atika, S.Pd
M53: Ngoro, ……………….…… 2026
A54: Mengetahui : | M54: Guru Mata Pelajaran
A55: Kepala SMA Negeri 1 Ngoro | D55: Wali Kelas X-1
A59: CHOIRUL IHSAN, S.Pd, M.M. | D59: KASIADI, S.Ag, M.Pd | M59: …..…………………………..
A60: NIP. 19720416 200801 1 019 | D60: NIP. 19720721 200604 1 009 | M60: …..…………………………..
A73: PEMERINTAH PROVINSI JAWA TIMUR
A74: DINAS PENDIDIKAN
A75: SEKOLAH MENENGAH ATAS NEGERI 1 NGORO
A76: Jalan Candi Jolotundo, Kutogirang, Ngoro Tepepon : 0321-6819922
A77: Website : www.sman1ngoro.sch.id Email : smanngoro@gmail.com
A78: MOJOKERTO 61385
A80: DAFTAR HADIR SISWA
A82: KELAS | C82: : X-2 | D82: MATA PELAJARAN | K82: : | L82: ……………………………….
A83: SEMESTER : | C83: : GASAL | D83: TAHUN PELAJARAN | K83: : | L83: 2026/2027
...

Sheet REKAP GW 2026-2027
A1: PEMERINTAH PROVINSI JAWA TIMUR
A2: DINAS PENDIDIKAN
A3: SEKOLAH MENENGAH ATAS NEGERI 1 NGORO
A4: Jalan Candi Jolotundo, Kutogirang, Ngoro Tepepon : 0321-6819922
A5: Website : www.sman1ngoro.sch.id Email : smanngoro@gmail.com
A7: DAFTAR NAMA GURU WALI
A8: TAHUN PELAJARAN 2026/2027
A10: NO | B10: NO INDUK | C10: NAMA SISWA | D10: L/P | E10: GURU WALI | F10: KELAS
A11: 1 | B11: 6038 | C11: DEWI FARAH MEILANI | D11: P | E11: Sujiati, S.Pd | F11: XI-1
A12: 2 | B12: 6024 | C12: CIKA VISEL HANIFA | D12: P | E12: Sujiati, S.Pd | F12: XI-3
A13: 3 | B13: 6043 | C13: DIAJENG OKTAVIA PUTRI | D13: P | E13: Sujiati, S.Pd | F13: XI-3
A14: 4 | B14: 6006 | C14: AZ ZHARO ADKHA FITRI | D14: P | E14: Sujiati, S.Pd | F14: XI-4
A15: 5 | B15: 5961 | C15: AHMAD KHOLIDUL IBAD | D15: L | E15: Sujiati, S.Pd | F15: XI-7
A16: 6 | B16: 5984 | C16: ANGGE TRI UTARI | D16: P | E16: Sujiati, S.Pd | F16: XI-7
A17: 7 | B17: 6040 | C17: DHEVA DWI OKTAFIONA | D17: P | E17: Sujiati, S.Pd | F17: XI-7
A18: 8 | B18: 5979 | C18: AMEL RAHMA FARADILAH | D18: P | E18: Sujiati, S.Pd | F18: XI-8
A19: 9 | B19: 6018 | C19: CANDRA KIRANA SASKIA PUTRI | D19: P | E19: Sujiati, S.Pd | F19: XI-8
A20: 10 | B20: 5632 | C20: ADELIA SHAFURA INDRI | D20: P | E20: Sujiati, S.Pd | F20: XII-4
A21: 11 | B21: 5639 | C21: AHMAD ADIT AFANDI | D21: L | E21: Sujiati, S.Pd | F21: XII-4
A22: 12 | B22: 5650 | C22: AISYAH ZAHRA SELFINITA HABIBAH | D22: P | E22: Sujiati, S.Pd | F22: XII-4
... A954: 944 | B954: 5944 | C954: YURIN NISWANILA RAMADANI | D954: P | E954: Rahmad Fanani, S.Pd | F954: XII-5

Sheet DATA X 
C5: L/P | D5: KELAS | I5: JUMLAH
D6: X-1 | E6: X-2 | F6: X-3 | G6: X-4
C7: L | D7: ='ABSEN X'!W10 -> 12 | E7: ='ABSEN X'!W89 -> 10 | F7: ='ABSEN X'!W161 -> 10 | G7: ='ABSEN X'!W233 -> 10 | I7: =SUM(D7:G7) -> 42
C8: P | D8: ='ABSEN X'!W11 -> 24 | E8: ='ABSEN X'!W90 -> 25 | F8: ='ABSEN X'!W162 -> 26 | G8: ='ABSEN X'!W234 -> 26 | I8: =SUM(D8:G8) -> 101
D9: ='ABSEN X'!W12 -> 36 | E9: ='ABSEN X'!W91 -> 35 | F9: ='ABSEN X'!W163 -> 36 | G9: ='ABSEN X'!W235 -> 36 | I9: =SUM(D9:G9) -> 143
D11: X-5 | E11: X-6 | F11: X-7 | G11: X-8 | H11: X-9
C12: L | D12: ='ABSEN X'!W305 -> 10 | E12: ='ABSEN X'!W377 -> 12 | F12: ='ABSEN X'!W449 -> 10 | G12: ='ABSEN X'!W521 -> 10 | H12: ='ABSEN X'!W593 -> 12 | I12: =SUM(D12:H12) -> 54
C13: P | D13: ='ABSEN X'!W306 -> 26 | E13: ='ABSEN X'!W378 -> 23 | F13: ='ABSEN X'!W450 -> 26 | G13: ='ABSEN X'!W522 -> 26 | H13: ='ABSEN X'!W594 -> 23 | I13: =SUM(D13:H13) -> 124
D14: ='ABSEN X'!W307 -> 36 | E14: ='ABSEN X'!W379 -> 35 | F14: ='ABSEN X'!W451 -> 36 | G14: ='ABSEN X'!W523 -> 36 | H14: ='ABSEN X'!W595 -> 35 | I14: =SUM(D14:H14) -> 178 | K14: UNTUK MENGINGAT JUMLAH SISWA DAN JENIS KELAMIN PER KELAS
C16: TOTAL SISWA KELAS X SEMGAS TP 2026/2027
C18: L | I18: =I7+I12 -> 96
C19: P | I19: =I8+I13 -> 225
C20: JUMLAH | I20: =I9+I14 -> 321
